2024-05-20 10:29:32,106 INFO    StreamThr :25513 [internal.py:wandb_internal():85] W&B internal server running at pid: 25513, started at: 2024-05-20 10:29:32.105545
2024-05-20 10:29:32,107 DEBUG   HandlerThread:25513 [handler.py:handle_request():158] handle_request: status
2024-05-20 10:29:32,111 INFO    WriterThread:25513 [datastore.py:open_for_write():87] open: /home/grad-min/mycode/CodeBertModel/wandb/run-20240520_102932-c45m4thv/run-c45m4thv.wandb
2024-05-20 10:29:32,111 DEBUG   SenderThread:25513 [sender.py:send():378] send: header
2024-05-20 10:29:32,136 DEBUG   SenderThread:25513 [sender.py:send():378] send: run
2024-05-20 10:29:32,617 ERROR   SenderThread:25513 [internal_api.py:execute():344] 404 response executing GraphQL.
2024-05-20 10:29:32,617 ERROR   SenderThread:25513 [internal_api.py:execute():345] {"errors":[{"message":"entity microsoft/unixcoder-base-nhead-2 not found during upsertBucket","path":["upsertBucket"]}],"data":{"upsertBucket":null}}
2024-05-20 10:29:32,617 ERROR   SenderThread:25513 [sender.py:send_run():970] It appears that you do not have permission to access the requested resource. Please reach out to the project owner to grant you access. If you have the correct permissions, verify that there are no issues with your networking setup.(Error 404: Not Found)
Traceback (most recent call last):
  File "/home/grad-min/.local/lib/python3.8/site-packages/wandb/sdk/lib/retry.py", line 131, in __call__
    result = self._call_fn(*args, **kwargs)
  File "/home/grad-min/.local/lib/python3.8/site-packages/wandb/sdk/internal/internal_api.py", line 340, in execute
    return self.client.execute(*args, **kwargs)  # type: ignore
  File "/home/grad-min/.local/lib/python3.8/site-packages/wandb/vendor/gql-0.2.0/wandb_gql/client.py", line 52, in execute
    result = self._get_result(document, *args, **kwargs)
  File "/home/grad-min/.local/lib/python3.8/site-packages/wandb/vendor/gql-0.2.0/wandb_gql/client.py", line 60, in _get_result
    return self.transport.execute(document, *args, **kwargs)
  File "/home/grad-min/.local/lib/python3.8/site-packages/wandb/sdk/lib/gql_request.py", line 59, in execute
    request.raise_for_status()
  File "/usr/lib/python3/dist-packages/requests/models.py", line 940, in raise_for_status
    raise HTTPError(http_error_msg, response=self)
requests.exceptions.HTTPError: 404 Client Error: Not Found for url: https://api.wandb.ai/graphql

During handling of the above exception, another exception occurred:

Traceback (most recent call last):
  File "/home/grad-min/.local/lib/python3.8/site-packages/wandb/sdk/internal/sender.py", line 968, in send_run
    server_run = self._init_run(run, config_value_dict)
  File "/home/grad-min/.local/lib/python3.8/site-packages/wandb/sdk/internal/sender.py", line 1013, in _init_run
    server_run, inserted, server_messages = self._api.upsert_run(
  File "/home/grad-min/.local/lib/python3.8/site-packages/wandb/apis/normalize.py", line 73, in wrapper
    raise err
  File "/home/grad-min/.local/lib/python3.8/site-packages/wandb/apis/normalize.py", line 41, in wrapper
    return func(*args, **kwargs)
  File "/home/grad-min/.local/lib/python3.8/site-packages/wandb/sdk/internal/internal_api.py", line 2188, in upsert_run
    response = self.gql(
  File "/home/grad-min/.local/lib/python3.8/site-packages/wandb/sdk/internal/internal_api.py", line 312, in gql
    ret = self._retry_gql(
  File "/home/grad-min/.local/lib/python3.8/site-packages/wandb/sdk/lib/retry.py", line 147, in __call__
    retry_timedelta_triggered = check_retry_fn(e)
  File "/home/grad-min/.local/lib/python3.8/site-packages/wandb/util.py", line 965, in check_retry_fn
    return fallback_retry_fn(e)
  File "/home/grad-min/.local/lib/python3.8/site-packages/wandb/util.py", line 907, in no_retry_auth
    raise CommError(
wandb.errors.CommError: It appears that you do not have permission to access the requested resource. Please reach out to the project owner to grant you access. If you have the correct permissions, verify that there are no issues with your networking setup.(Error 404: Not Found)
2024-05-20 10:29:32,733 DEBUG   HandlerThread:25513 [handler.py:handle_request():158] handle_request: shutdown
2024-05-20 10:29:32,733 INFO    HandlerThread:25513 [handler.py:finish():882] shutting down handler
2024-05-20 10:29:33,136 INFO    WriterThread:25513 [datastore.py:close():296] close: /home/grad-min/mycode/CodeBertModel/wandb/run-20240520_102932-c45m4thv/run-c45m4thv.wandb
2024-05-20 10:29:33,619 INFO    SenderThread:25513 [sender.py:finish():1545] shutting down sender
